Workbook

Sheet Assumptions
A1: AVERRA — model inputs (blue = input · yellow = key assumption to confirm · black = formula)
A3: ID | B3: Input | C3: Value | D3: Unit | E3: Status | F3: Source / basis
A4: M1 | B4: India population aged 60+ (2022) | C4: 149000000 | D4: people | E4: Sourced | F4: UNFPA India Ageing Report 2023 (The National, 28 Sep 2023)
A5: M2 | B5: 60+ share of population (2022) | C5: 0.105 | D5: % | E5: Sourced | F5: UNFPA India Ageing Report 2023
A6: M3 | B6: PD prevalence, age 60+ | C6: 0.003089 | D6: rate | E6: Sourced | F6: Je et al., Anand (Gujarat) 2019–20, via Khurana & Gourie-Devi, Cureus 2025
A7: M4 | B7: Essential-tremor crude prevalence | C7: 0.0008996 | D7: rate | E7: Sourced | F7: Chin et al., rural Gujarat, Mov Disord 2021 (single study)
A8: M5 | B8: Urban share of population | C8: 0.311 | D8: % | E8: Sourced | F8: Census of India 2011 (dated)
A9: M6 | B9: Urban patients under regular neurologist follow-up | C9: 0.4 | D9: % | E9: Estimate | F9: Founders' estimate — validate in discovery
A10: M7 | B10: PD + ET patients whose tremor disrupts eating | C10: 0.5 | D10: % | E10: Estimate | F10: Founders' estimate — validate with neurologists / OTs
A11: M8 | B11: Device replacement life | C11: 3 | D11: years | E11: Estimate | F11: Engineering estimate
A12: P1 | B12: TremoSense launch price (incl. GST) — RECOMMENDED | C12: 9999 | D12: ₹ | E12: Decision | F12: Chosen from Price Matrix: lowest round price with ≥30% contribution margin at Scenario B cost
A13: P2 | B13: Lowest viable TremoSense price at verified C cost (NOT used in plan) | C13: 6999 | D13: ₹ | E13: Option | F13: ≈42% contribution at C; an affordability option once profitability is secure
A14: P13 | B14: TremoSense price from M19, once Scenario C cost is verified (incl. GST) | C14: 8999 | D14: ₹ | E14: Decision | F14: Price cut shared with customers after verified cost reduction; still ≥40% contribution at C
A15: P3 | B15: ParkinSense wellness wearable price (incl. GST) | C15: 7999 | D15: ₹ | E15: Decision | F15: Hypothesis to test; below Amazfit Helio Strap (₹12,000+), Google Fitbit Air (₹13,999), WHOOP One (₹20,890/yr) and Garmin Cirqa (₹25,990); positive contribution after CAC
... A34: U4 | B34: Subscription attach rate (ParkinSense) | C34: 0.4 | D34: % | E34: Estimate | F34: Share of buyers who subscribe
A35: F1 | B35: Contingency on costs | C35: 0.1 | D35: % | E35: Policy
A36: F2 | B36: Buffer on peak funding gap | C36: 0.2 | D36: % | E36: Policy | F36: Covers ~2–3 months' delay
A37: F3 | B37: SISFS proof-of-concept grant — APPLIED, NOT SECURED | C37: 2000000 | D37: ₹ | E37: Applied | F37: Startup India Seed Fund Scheme cap ₹20 L, milestone-based (ClearTax)
A38: F4 | B38: ESOP pool at pre-seed (% of post-money) | C38: 0.05 | D38: % | E38: Policy | F38: Small pool now; top-up at seed round
A39: F5 | B39: Loaded engineering cost per person-month | C39: 125000 | D39: ₹ | E39: Estimate | F39: Cost-to-duplicate rate (≈₹15 LPA CTC) — assumption
A40: F6 | B40: USD/INR | C40: 95.71 | D40: ₹/$ | E40: Sourced | F40: Traders Union, 12 Oct 2026
A41: F7 | B41: Target investor dilution — low | C41: 0.15 | D41: % | E41: Target | F41: Founders' goal
A42: F8 | B42: Target investor dilution — high | C42: 0.2 | D42: % | E42: Target | F42: Founders' goal
A43: F9 | B43: Grant receipt month (if awarded) | C43: 3 | D43: month # | E43: Assumption
A44: F10 | B44: PROPOSED pre-money — working negotiation target | C44: 7500000 | D44: ₹ | E44: Target | F44: Founders' ask; above the cost floor and Berkus cross-check; NOT an independently established valuation
A45: F11 | B45: Conservative pre-money alternative | C45: 6000000 | D45: ₹ | E45: Target | F45: ≈ Berkus-style scorecard result
A46: F12 | B46: Ambitious pre-money alternative | C46: 10000000 | D46: ₹ | E46: Target | F46: Only if the premium can be substantiated
A47: S1 | B47: Steady-state TremoSense units/month (M15–M18) | C47: 50 | D47: units | E47: Plan

Sheet TremoSense Costs
A1: TremoSense unit cost — three scenarios (₹ per unit)
A3: Line | B3: A · Prototype / very low volume (1–20) | C3: B · Small batch (100–500) | D3: C · Scaled, after verified reductions (≥1,000) | E3: Evidence
A4: MCU + IMU (XIAO nRF52840 Sense → bare module in C) | B4: =15.9*Assumptions!$C$40 -> 1521.789 | C4: =13.9*Assumptions!$C$40 -> 1330.369 | D4: 520 | E4: A/B: Seeed list $15.90 / $13.90 (10+) — DOCUMENTED. C: bare nRF52840 module + LSM6DS3 on custom PCB — ESTIMATE, needs quote
A5: Servos ×2 (MG92B → direct-sourced micro servos in C) | B5: 1600 | C5: 1400 | D5: 500 | E5: A: UK retail £8 each (The Pi Hut) ≈ ₹800 — DOCUMENTED reference; B/C: ESTIMATE, needs supplier quote
A6: Power: XL6009 boost converter + 1250 mAh LiPo | B6: 570 | C6: 470 | D6: 380 | E6: ESTIMATE — replace with receipts / quotes
A7: Interconnect: 1500 µF capacitor, wiring, connectors (→ carrier PCB in B → integrated PCBA in C) | B7: 120 | C7: 280 | D7: 550 | E7: C includes PCB fab + SMT assembly — ESTIMATE, needs quote
A8: Enclosure, gimbal & food-safe spoon head | B8: 250 | C8: 600 | D8: 350 | E8: A: filament only; B: printed + finished; C: moulded part (tooling in Assumptions C6, not in unit cost)
A9: Assembly labour | B9: 500 | C9: 400 | D9: 200 | E9: A: ~2 h; B: ~1.5 h; C: line assembly — ESTIMATE
A10: Testing & quality control | B10: 150 | C10: 200 | D10: 120 | E10: Bench check on tremor simulator + burn-in — ESTIMATE
A11: Packaging + manual | B11: 150 | C11: 150 | D11: 100 | E11: ESTIMATE
A12: Unit COGS | B12: =SUM(B4:B11) -> 4861.789 | C12: =SUM(C4:C11) -> 4830.369 | D12: =SUM(D4:D11) -> 2720
A13: of which electronics + PCB (the '₹2,000 target' line) | B13: =SUM(B4:B7) -> 3811.789 | C13: =SUM(C4:C7) -> 3480.369 | D13: =SUM(D4:D7) -> 1950 | E13: Today's prototype parts ≈₹4,060 (A, rows 4–8 excl. labour). ₹2,000 is the C electronics TARGET — not today's cost.
A14: Prototype parts only (A rows 4–8) | B14: =SUM(B4:B8) -> 4061.789
A16: Economics: A and B at the ₹9,999 launch price; C at the ₹8,999 plan price from M19
A17: Retail price incl. GST | B17: =Assumptions!$C$12 -> 9999 | C17: =Assumptions!$C$12 -> 9999 | D17: =Assumptions!$C$14 -> 8999
A18: Price ex-GST | B18: =B17/(1+Assumptions!$C$18) -> 9522.8571 | C18: =C17/(1+Assumptions!$C$18) -> 9522.8571 | D18: =D17/(1+Assumptions!$C$18) -> 8570.4762
A19: Channel margin (clinic / OT) | B19: =B18*Assumptions!$C$20 -> 1428.4286 | C19: =C18*Assumptions!$C$20 -> 1428.4286 | D19: =D18*Assumptions!$C$20 -> 1285.5714
A20: Net revenue to AVERRA | B20: =B18-B19 -> 8094.4286 | C20: =C18-C19 -> 8094.4286 | D20: =D18-D19 -> 7284.9048
A21: Unit COGS | B21: =B12 -> 4861.789 | C21: =C12 -> 4830.369 | D21: =D12 -> 2720
A22: Warranty reserve | B22: =B18*IF("B"="B",0.08,Assumptions!$C$25) -> 761.82857 | C22: =C18*IF("C"="B",0.08,Assumptions!$C$25) -> 476.14286 | D22: =D18*IF("D"="B",0.08,Assumptions!$C$25) -> 428.52381 | E22: Scenario A carries an 8% warranty reserve (lower reliability).
A23: Fulfilment | B23: =Assumptions!$C$26 -> 250 | C23: =Assumptions!$C$26 -> 250 | D23: =Assumptions!$C$26 -> 250
A24: Contribution per unit | B24: =B20-B21-B22-B23 -> 2220.811 | C24: =C20-C21-C22-C23 -> 2537.9167 | D24: =D20-D21-D22-D23 -> 3886.381
A25: Contribution margin (of net revenue) | B25: =IF(B20=0,0,B24/B20) -> 0.27436291 | C25: =IF(C20=0,0,C24/C20) -> 0.31353871 | D25: =IF(D20=0,0,D24/D20) -> 0.53348411
A26: Break-even units / month vs steady-state fixed costs | B26: =IF(B24<=0,"never",Forecast!$C$81/B24) -> 226.81467 | C26: =IF(C24<=0,"never",Forecast!$C$81/C24) -> 198.4748 | D26: =IF(D24<=0,"never",Forecast!$C$81/D24) -> 129.60966 | E26: Fixed costs = Year-3 average monthly fixed costs (Forecast!C81).
A27: Gross margin = (net revenue − COGS) ÷ net revenue | B27: =IF(B20=0,0,(B20-B21)/B20) -> 0.399366 | C27: =IF(C20=0,0,(C20-C21)/C20) -> 0.40324768 | D27: =IF(D20=0,0,(D20-D21)/D20) -> 0.62662518 | E27: Gross margin excludes warranty and fulfilment; contribution margin (row 25) includes them.

Sheet Price Matrix
A1: TremoSense — contribution per unit by price × cost scenario (clinic channel)
A3: Retail price (incl. GST) | B3: A · contribution | C3: A · margin | D3: B · contribution | E3: B · margin | F3: C · contribution | G3: C · margin | H3: Verdict
A4: 4999 | B4: =(A4/(1+Assumptions!$C$18))*(1-Assumptions!$C$20)-'TremoSense Costs'!B12-(A4/(1+Assumptions!$C$18))*0.08-Assumptions!$C$26 -> -1445.8557 | C4: =IF((A4/(1+Assumptions!$C$18))*(1-Assumptions!$C$20)=0,0,B4/((A4/(1+Assumptions!$C$18))*(1-Assumptions!$C$20))) -> -0.35728286 | D4: =(A4/(1+Assumptions!$C$18))*(1-Assumptions!$C$20)-'TremoSense Costs'!C12-(A4/(1+Assumptions!$C$18))*Assumptions!$C$25-Assumptions!$C$26 -> -1271.6071 | E4: =IF((A4/(1+Assumptions!$C$18))*(1-Assumptions!$C$20)=0,0,D4/((A4/(1+Assumptions!$C$18))*(1-Assumptions!$C$20))) -> -0.3142246 | F4: =(A4/(1+Assumptions!$C$18))*(1-Assumptions!$C$20)-'TremoSense Costs'!D12-(A4/(1+Assumptions!$C$18))*Assumptions!$C$25-Assumptions!$C$26 -> 838.7619 | G4: =IF((A4/(1+Assumptions!$C$18))*(1-Assumptions!$C$20)=0,0,F4/((A4/(1+Assumptions!$C$18))*(1-Assumptions!$C$20))) -> 0.20726498 | H4: =IF(E4>=0.3,"Viable at small batch",IF(G4>=0.3,"Viable only after verified C cost",IF(G4>0,"Thin even at C","Loss-making"))) -> Thin even at C
A5: 5999 | B5: =(A5/(1+Assumptions!$C$18))*(1-Assumptions!$C$20)-'TremoSense Costs'!B12-(A5/(1+Assumptions!$C$18))*0.08-Assumptions!$C$26 -> -712.52233 | C5: =IF((A5/(1+Assumptions!$C$18))*(1-Assumptions!$C$20)=0,0,B5/((A5/(1+Assumptions!$C$18))*(1-Assumptions!$C$20))) -> -0.14672023 | D5: =(A5/(1+Assumptions!$C$18))*(1-Assumptions!$C$20)-'TremoSense Costs'!C12-(A5/(1+Assumptions!$C$18))*Assumptions!$C$25-Assumptions!$C$26 -> -509.70233 | E5: =IF((A5/(1+Assumptions!$C$18))*(1-Assumptions!$C$20)=0,0,D5/((A5/(1+Assumptions!$C$18))*(1-Assumptions!$C$20))) -> -0.10495621 | F5: =(A5/(1+Assumptions!$C$18))*(1-Assumptions!$C$20)-'TremoSense Costs'!D12-(A5/(1+Assumptions!$C$18))*Assumptions!$C$25-Assumptions!$C$26 -> 1600.6667 | G5: =IF((A5/(1+Assumptions!$C$18))*(1-Assumptions!$C$20)=0,0,F5/((A5/(1+Assumptions!$C$18))*(1-Assumptions!$C$20))) -> 0.32960395 | H5: =IF(E5>=0.3,"Viable at small batch",IF(G5>=0.3,"Viable only after verified C cost",IF(G5>0,"Thin even at C","Loss-making"))) -> Viable only after verified C cost
A6: 6999 | B6: =(A6/(1+Assumptions!$C$18))*(1-Assumptions!$C$20)-'TremoSense Costs'!B12-(A6/(1+Assumptions!$C$18))*0.08-Assumptions!$C$26 -> 20.811 | C6: =IF((A6/(1+Assumptions!$C$18))*(1-Assumptions!$C$20)=0,0,B6/((A6/(1+Assumptions!$C$18))*(1-Assumptions!$C$20))) -> 0.0036730541 | D6: =(A6/(1+Assumptions!$C$18))*(1-Assumptions!$C$20)-'TremoSense Costs'!C12-(A6/(1+Assumptions!$C$18))*Assumptions!$C$25-Assumptions!$C$26 -> 252.20243 | E6: =IF((A6/(1+Assumptions!$C$18))*(1-Assumptions!$C$20)=0,0,D6/((A6/(1+Assumptions!$C$18))*(1-Assumptions!$C$20))) -> 0.04451267 | F6: =(A6/(1+Assumptions!$C$18))*(1-Assumptions!$C$20)-'TremoSense Costs'!D12-(A6/(1+Assumptions!$C$18))*Assumptions!$C$25-Assumptions!$C$26 -> 2362.5714 | G6: =IF((A6/(1+Assumptions!$C$18))*(1-Assumptions!$C$20)=0,0,F6/((A6/(1+Assumptions!$C$18))*(1-Assumptions!$C$20))) -> 0.41698394 | H6: =IF(E6>=0.3,"Viable at small batch",IF(G6>=0.3,"Viable only after verified C cost",IF(G6>0,"Thin even at C","Loss-making"))) -> Viable only after verified C cost
A7: 7999 | B7: =(A7/(1+Assumptions!$C$18))*(1-Assumptions!$C$20)-'TremoSense Costs'!B12-(A7/(1+Assumptions!$C$18))*0.08-Assumptions!$C$26 -> 754.14433 | C7: =IF((A7/(1+Assumptions!$C$18))*(1-Assumptions!$C$20)=0,0,B7/((A7/(1+Assumptions!$C$18))*(1-Assumptions!$C$20))) -> 0.11646332 | D7: =(A7/(1+Assumptions!$C$18))*(1-Assumptions!$C$20)-'TremoSense Costs'!C12-(A7/(1+Assumptions!$C$18))*Assumptions!$C$25-Assumptions!$C$26 -> 1014.1072 | E7: =IF((A7/(1+Assumptions!$C$18))*(1-Assumptions!$C$20)=0,0,D7/((A7/(1+Assumptions!$C$18))*(1-Assumptions!$C$20))) -> 0.15660966 | F7: =(A7/(1+Assumptions!$C$18))*(1-Assumptions!$C$20)-'TremoSense Costs'!D12-(A7/(1+Assumptions!$C$18))*Assumptions!$C$25-Assumptions!$C$26 -> 3124.4762 | G7: =IF((A7/(1+Assumptions!$C$18))*(1-Assumptions!$C$20)=0,0,F7/((A7/(1+Assumptions!$C$18))*(1-Assumptions!$C$20))) -> 0.4825162 | H7: =IF(E7>=0.3,"Viable at small batch",IF(G7>=0.3,"Viable only after verified C cost",IF(G7>0,"Thin even at C","Loss-making"))) -> Viable only after verified C cost
A8: 8999 | B8: =(A8/(1+Assumptions!$C$18))*(1-Assumptions!$C$20)-'TremoSense Costs'!B12-(A8/(1+Assumptions!$C$18))*0.08-Assumptions!$C$26 -> 1487.4777 | C8: =IF((A8/(1+Assumptions!$C$18))*(1-Assumptions!$C$20)=0,0,B8/((A8/(1+Assumptions!$C$18))*(1-Assumptions!$C$20))) -> 0.20418629 | D8: =(A8/(1+Assumptions!$C$18))*(1-Assumptions!$C$20)-'TremoSense Costs'!C12-(A8/(1+Assumptions!$C$18))*Assumptions!$C$25-Assumptions!$C$26 -> 1776.012 | E8: =IF((A8/(1+Assumptions!$C$18))*(1-Assumptions!$C$20)=0,0,D8/((A8/(1+Assumptions!$C$18))*(1-Assumptions!$C$20))) -> 0.24379343 | F8: =(A8/(1+Assumptions!$C$18))*(1-Assumptions!$C$20)-'TremoSense Costs'!D12-(A8/(1+Assumptions!$C$18))*Assumptions!$C$25-Assumptions!$C$26 -> 3886.381 | G8: =IF((A8/(1+Assumptions!$C$18))*(1-Assumptions!$C$20)=0,0,F8/((A8/(1+Assumptions!$C$18))*(1-Assumptions!$C$20))) -> 0.53348411 | H8: =IF(E8>=0.3,"Viable at small batch",IF(G8>=0.3,"Viable only after verified C cost",IF(G8>0,"Thin even at C","Loss-making"))) -> Viable only after verified C cost
A9: 9999 | B9: =(A9/(1+Assumptions!$C$18))*(1-Assumptions!$C$20)-'TremoSense Costs'!B12-(A9/(1+Assumptions!$C$18))*0.08-Assumptions!$C$26 -> 2220.811 | C9: =IF((A9/(1+Assumptions!$C$18))*(1-Assumptions!$C$20)=0,0,B9/((A9/(1+Assumptions!$C$18))*(1-Assumptions!$C$20))) -> 0.27436291 | D9: =(A9/(1+Assumptions!$C$18))*(1-Assumptions!$C$20)-'TremoSense Costs'!C12-(A9/(1+Assumptions!$C$18))*Assumptions!$C$25-Assumptions!$C$26 -> 2537.9167 | E9: =IF((A9/(1+Assumptions!$C$18))*(1-Assumptions!$C$20)=0,0,D9/((A9/(1+Assumptions!$C$18))*(1-Assumptions!$C$20))) -> 0.31353871 | F9: =(A9/(1+Assumptions!$C$18))*(1-Assumptions!$C$20)-'TremoSense Costs'!D12-(A9/(1+Assumptions!$C$18))*Assumptions!$C$25-Assumptions!$C$26 -> 4648.2857 | G9: =IF((A9/(1+Assumptions!$C$18))*(1-Assumptions!$C$20)=0,0,F9/((A9/(1+Assumptions!$C$18))*(1-Assumptions!$C$20))) -> 0.57425743 | H9: =IF(E9>=0.3,"Viable at small batch",IF(G9>=0.3,"Viable only after verified C cost",IF(G9>0,"Thin even at C","Loss-making"))) -> Viable at small batch
A10: 12999 | B10: =(A10/(1+Assumptions!$C$18))*(1-Assumptions!$C$20)-'TremoSense Costs'!B12-(A10/(1+Assumptions!$C$18))*0.08-Assumptions!$C$26 -> 4420.811 | C10: =IF((A10/(1+Assumptions!$C$18))*(1-Assumptions!$C$20)=0,0,B10/((A10/(1+Assumptions!$C$18))*(1-Assumptions!$C$20))) -> 0.42010938 | D10: =(A10/(1+Assumptions!$C$18))*(1-Assumptions!$C$20)-'TremoSense Costs'!C12-(A10/(1+Assumptions!$C$18))*Assumptions!$C$25-Assumptions!$C$26 -> 4823.631 | E10: =IF((A10/(1+Assumptions!$C$18))*(1-Assumptions!$C$20)=0,0,D10/((A10/(1+Assumptions!$C$18))*(1-Assumptions!$C$20))) -> 0.45838934 | F10: =(A10/(1+Assumptions!$C$18))*(1-Assumptions!$C$20)-'TremoSense Costs'!D12-(A10/(1+Assumptions!$C$18))*Assumptions!$C$25-Assumptions!$C$26 -> 6934 | G10: =IF((A10/(1+Assumptions!$C$18))*(1-Assumptions!$C$20)=0,0,F10/((A10/(1+Assumptions!$C$18))*(1-Assumptions!$C$20))) -> 0.65893757 | H10: =IF(E10>=0.3,"Viable at small batch",IF(G10>=0.3,"Viable only after verified C cost",IF(G10>0,"Thin even at C","Loss-making"))) -> Viable at small batch
A12: Recommendation | B12: Launch at ₹9,999 (≥30% margin at B). Do not price below ₹8,999 until Scenario C cost is verified by quotes. Move to ₹6,999 only after that.
A14: Channel options at the launch price (Scenario B cost) — none validated yet
A15: Channel | B15: Net revenue / unit | C15: Contribution / unit | D15: Margin | E15: Notes
A16: Direct online | B16: =Assumptions!$C$12/(1+Assumptions!$C$18) -> 9522.8571 | C16: =B16-'TremoSense Costs'!C12-Assumptions!$C$12/(1+Assumptions!$C$18)*Assumptions!$C$25-Assumptions!$C$26 -> 3966.3453 | D16: =IF(B16=0,0,C16/B16) -> 0.41650791 | E16: No channel margin; pays its own CAC
A17: Clinic partnership | B17: =Assumptions!$C$12/(1+Assumptions!$C$18)*(1-Assumptions!$C$20) -> 8094.4286 | C17: =B17-'TremoSense Costs'!C12-Assumptions!$C$12/(1+Assumptions!$C$18)*Assumptions!$C$25-Assumptions!$C$26 -> 2537.9167 | D17: =IF(B17=0,0,C17/B17) -> 0.31353871 | E17: 15% margin to clinic
A18: Occupational-therapy centres | B18: =Assumptions!$C$12/(1+Assumptions!$C$18)*(1-Assumptions!$C$20) -> 8094.4286 | C18: =B18-'TremoSense Costs'!C12-Assumptions!$C$12/(1+Assumptions!$C$18)*Assumptions!$C$25-Assumptions!$C$26 -> 2537.9167 | D18: =IF(B18=0,0,C18/B18) -> 0.31353871 | E18: Same terms as clinics
A19: Institutional procurement | B19: =Assumptions!$C$12/(1+Assumptions!$C$18)*(1-Assumptions!$C$22) -> 8570.5714 | C19: =B19-'TremoSense Costs'!C12-Assumptions!$C$12/(1+Assumptions!$C$18)*Assumptions!$C$25-Assumptions!$C$26 -> 3014.0596 | D19: =IF(B19=0,0,C19/B19) -> 0.35167545 | E19: 10% discount, 60-day terms
A20: No-cost EMI (direct) | B20: =Assumptions!$C$12/(1+Assumptions!$C$18)-Assumptions!$C$12*Assumptions!$C$24 -> 9122.8971 | C20: =B20-'TremoSense Costs'!C12-Assumptions!$C$12/(1+Assumptions!$C$18)*Assumptions!$C$25-Assumptions!$C$26 -> 3566.3853 | D20: =IF(B20=0,0,C20/B20) -> 0.39092683 | E20: Subvention borne by AVERRA
A22: Rental via OT clinic (Scenario B device) | B22: =Assumptions!$C$23/1.18*(1-Assumptions!$C$20) -> 575.55085 | E22: Net monthly rental to AVERRA
A23: Months to recover device cost + two-way fulfilment | B23: =('TremoSense Costs'!C12+2*Assumptions!$C$26)/B22 -> 9.2613346 | E23: After this, rental is contribution; refurbishment between renters not yet costed

Sheet Unit Economics
A1: Unit economics — estimates, no customers yet
A3: Line | B3: TremoSense (launch, Scenario B) | C3: ParkinSense wearable | D3: ParkinSense subscription (/month) | E3: ParkinSense RUO kit
A4: Price incl. GST | B4: =Assumptions!$C$12 -> 9999 | C4: =Assumptions!$C$15 -> 7999 | D4: =Assumptions!$C$16 -> 199 | E4: =Assumptions!$C$17 -> 74999
A5: Price ex-GST | B5: =B4/(1+Assumptions!$C$18) -> 9522.8571 | C5: =C4/(1+Assumptions!$C$19) -> 6778.8136 | D5: =D4/(1+Assumptions!$C$19) -> 168.64407 | E5: =E4/(1+Assumptions!$C$19) -> 63558.475
A6: Channel / marketplace | B6: =B5*Assumptions!$C$20 -> 1428.4286 | C6: =C5*Assumptions!$C$21 -> 677.88136 | D6: 0 | E6: 0
A7: Net revenue | B7: =B5-B6 -> 8094.4286 | C7: =C5-C6 -> 6100.9322 | D7: =D5-D6 -> 168.64407 | E7: =E5-E6 -> 63558.475
A8: COGS / service cost | B8: ='TremoSense Costs'!C12 -> 4830.369 | C8: =Assumptions!$C$27 -> 3530 | D8: =Assumptions!$C$28 -> 40 | E8: =5*Assumptions!$C$27+Assumptions!$C$29 -> 22650
A9: Warranty | B9: =B5*Assumptions!$C$25 -> 476.14286 | C9: =C5*Assumptions!$C$25 -> 338.94068 | D9: 0 | E9: 0
A10: Fulfilment | B10: =Assumptions!$C$26 -> 250 | C10: =Assumptions!$C$26 -> 250 | D10: 0 | E10: =Assumptions!$C$26 -> 250
A11: Contribution | B11: =B7-B8-B9-B10 -> 2537.9167 | C11: =C7-C8-C9-C10 -> 1981.9915 | D11: =D7-D8-D9-D10 -> 128.64407 | E11: =E7-E8-E9-E10 -> 40658.475
A12: Contribution margin | B12: =IF(B7=0,0,B11/B7) -> 0.31353871 | C12: =IF(C7=0,0,C11/C7) -> 0.324867 | D12: =IF(D7=0,0,D11/D7) -> 0.76281407 | E12: =IF(E7=0,0,E11/E7) -> 0.63970186
A13: Gross margin (before warranty & fulfilment) | B13: =IF(B7=0,0,(B7-B8)/B7) -> 0.40324768 | C13: =IF(C7=0,0,(C7-C8)/C7) -> 0.4213999 | D13: =IF(D7=0,0,(D7-D8)/D7) -> 0.76281407 | E13: =IF(E7=0,0,(E7-E8)/E7) -> 0.64363525
A15: CAC / LTV / payback
A16: Metric | B16: TremoSense | C16: ParkinSense (wearable buyer) | F16: Basis
A17: CAC | B17: =Forecast!$AX$5/Forecast!$AX$6 -> 1078.8462 | C17: =Assumptions!$C$33 -> 1500 | F17: TremoSense: M12–M36 outreach + sales-lead spend ÷ units sold (plan). ParkinSense: assumption U3
A18: Subscriber lifetime (months) | B18: 0 | C18: =1/Assumptions!$C$31 -> 20 | F18: 1 ÷ churn
A19: LTV (contribution, undiscounted) | B19: =B11*(1+Assumptions!$C$32) -> 3553.0834 | C19: =C11+Assumptions!$C$34*D11*C18 -> 3011.1441 | F19: TremoSense: first sale + 40% repurchase. ParkinSense: device + attach × subscription × lifetime
A20: LTV : CAC | B20: =IF(B17=0,0,B19/B17) -> 3.2934106 | C20: =IF(C17=0,0,C19/C17) -> 2.0074294 | F20: Target ≥3×
A21: Payback (months) | B21: =IF(B11>=B17,0,99) -> 0 | C21: =IF(C11>=C17,0,(C17-C11)/(Assumptions!$C$34*D11)) -> 0 | F21: Months of contribution to recover CAC

Sheet Market
A1: Bottom-up TAM / SAM / SOM — India beachhead segments
A3: Line | B3: ParkinSense (movement-insight segment) | C3: TremoSense | D3: Formula / note | E3: ParkinSense — general wearable (upside)
A4: Implied total population | B4: =Assumptions!$C$4/Assumptions!$C$5 -> 1.4190476e+09 | C4: =Assumptions!$C$4/Assumptions!$C$5 -> 1.4190476e+09 | D4: 60+ count ÷ 60+ share
A5: People with PD aged 60+ | B5: =Assumptions!$C$4*Assumptions!$C$6 -> 460261 | C5: =Assumptions!$C$4*Assumptions!$C$6 -> 460261 | D5: GBD-based cross-check ≈5.76 lakh all ages
A6: People with essential tremor | B6: 0 | C6: =B4*Assumptions!$C$7 -> 1276575.2 | D6: TremoSense only
A7: TAM customers | B7: =B5 -> 460261 | C7: =(C5+C6)*Assumptions!$C$10 -> 868418.12 | D7: ParkinSense beachhead = PD households seeking movement insights; general wellness market NOT sized (no sourced Indian figure) | E7: =B25 -> 35000000
A8: Annual revenue per customer (ex-GST) | B8: ='Unit Economics'!C5/Assumptions!$C$11+Assumptions!$C$34*'Unit Economics'!D5*12 -> 3069.096 | C8: ='Unit Economics'!B5/Assumptions!$C$11 -> 3174.2857 | D8: Device ÷ life (+ attach × 12 months subscription) | E8: =B8 -> 3069.096
A9: TAM (₹/year) | B9: =B7*B8 -> 1.4125852e+09 | C9: =C7*C8 -> 2.7566072e+09 | E9: =E7*E8 -> 1.0741836e+11
A10: SAM customers (urban × under follow-up) | B10: =B7*Assumptions!$C$8*Assumptions!$C$9 -> 57256.468 | C10: =C7*Assumptions!$C$8*Assumptions!$C$9 -> 108031.21 | E10: =E7*B26 -> 980000
A11: SAM (₹/year) | B11: =B10*B8 -> 1.757256e+08 | C11: =C10*C8 -> 3.4292194e+08 | E11: =E10*E8 -> 3.0077141e+09
A12: SOM: partner clinics (Mumbai + Pune, Year 3) | B12: 30 | C12: 30 | D12: Plan
A13: SOM: new customers per clinic per month | B13: 2 | C13: 4 | D13: Plan
A14: SOM: online / OT channel per month | B14: 60 | C14: 50 | D14: Plan (ParkinSense online covers the broader wellness audience)
A15: SOM customers (Year 3, annual) | B15: =B12*B13*12+B14*12 -> 1440 | C15: =C12*C13*12+C14*12 -> 2040 | D15: Channel capacity | E15: =E10*B27 -> 2450
A16: SOM (₹/year) | B16: =B15*B8 -> 4419498.3 | C16: =C15*C8 -> 6475542.9 | E16: =E15*E8 -> 7519285.3
A17: SOM % of SAM | B17: =IF(B11=0,0,B16/B11) -> 0.025149997 | C17: =IF(C11=0,0,C16/C11) -> 0.018883431 | E17: =IF(E11=0,0,E16/E11) -> 0.0025
E18: Not added to company totals or the forecast
A19: Company TAM (₹/year) | B19: =B9+C9 -> 4.1691924e+09
A20: Company SAM (₹/year) | B20: =B11+C11 -> 5.1864754e+08
A21: Company SOM (₹/year) | B21: =B16+C16 -> 10895041
A22: Revenues add across products; customer counts are never summed (a PD household may buy both).
A24: ParkinSense as a general wearable — inputs (upside view, not in plan totals)
A25: India smartwatch buyers per year (IDC, 2024) | B25: 35000000 | D25: IDC India: 35.0M smartwatches shipped in 2024 (total wearables 119.0M)
A26: Advanced / premium smartwatch share (IDC, 2024) | B26: 0.028 | D26: IDC: advanced smartwatches 2.8% of units; proxy for buyers at ParkinSense's price point
A27: SOM share of SAM customers (Year 3) | B27: 0.0025 | D27: ASSUMPTION: 0.25% of premium buyers via online channel
A30: General-wearable SOM range (Year 3, upside only)
A31: Case | B31: SOM share of SAM buyers | C31: Customers / year | D31: SOM (₹/year)
A32: Plan case | B32: =B27 -> 0.0025 | C32: =E10*B32 -> 2450 | D32: =C32*E8 -> 7519285.3
A33: Upside: marketing works | B33: 0.005 | C33: =E10*B33 -> 4900 | D33: =C33*E8 -> 15038571
A34: Strong upside | B34: 0.01 | C34: =E10*B34 -> 9800 | D34: =C34*E8 -> 30077141

Sheet Forecast
A1: Monthly cash plan — Phase 1 PROVE (M1–M6) → Phase 2 LAUNCH (M7–M18) → SCALE (M19–M36). M1 = July 2027
A3: Line (₹) | B3: Product | C3: Phase | D3: M1 Jul-27 | E3: M2 Aug-27 | F3: M3 Sep-27 | G3: M4 Oct-27 | H3: M5 Nov-27 | I3: M6 Dec-27 | J3: M7 Jan-28 | K3: M8 Feb-28 | L3: M9 Mar-28 | M3: M10 Apr-28 | N3: M11 May-28 | O3: M12 Jun-28 | P3: M13 Jul-28 | Q3: M14 Aug-28 | R3: M15 Sep-28 | S3: M16 Oct-28 | T3: M17 Nov-28 | U3: M18 Dec-28 | V3: M19 Jan-29 | W3: M20 Feb-29 | X3: M21 Mar-29 | Y3: M22 Apr-29 | Z3: M23 May-29 | AA3: M24 Jun-29 | AB3: M25 Jul-29 | AC3: M26 Aug-29 | AD3: M27 Sep-29 | AE3: M28 Oct-29 | AF3: M29 Nov-29 | AG3: M30 Dec-29 | AH3: M31 Jan-30 | AI3: M32 Feb-30 | AJ3: M33 Mar-30 | AK3: M34 Apr-30 | AL3: M35 May-30 | AM3: M36 Jun-30 | AN3: Year 1 | AO3: Phase 1 (M1–6) | AP3: Phase 2 (M7–18) | AQ3: Year 2 | AR3: Year 3
A4: Founder stipends (2×₹15k Phase 1 · 2×₹30k M7–24 · 2×₹45k Y3) | B4: Shared | D4: 30000 | E4: 30000 | F4: 30000 | G4: 30000 | H4: 30000 | I4: 30000 | J4: 60000 | K4: 60000 | L4: 60000 | M4: 60000 | N4: 60000 | O4: 60000 | P4: 60000 | Q4: 60000 | R4: 60000 | S4: 60000 | T4: 60000 | U4: 60000 | V4: 60000 | W4: 60000 | X4: 60000 | Y4: 60000 | Z4: 60000 | AA4: 60000 | AB4: 90000 | AC4: 90000 | AD4: 90000 | AE4: 90000 | AF4: 90000 | AG4: 90000 | AH4: 90000 | AI4: 90000 | AJ4: 90000 | AK4: 90000 | AL4: 90000 | AM4: 90000 | AN4: =SUM(D4:O4) -> 540000 | AO4: =SUM(D4:I4) -> 180000 | AP4: =SUM(J4:U4) -> 720000 | AQ4: =SUM(P4:AA4) -> 720000 | AR4: =SUM(AB4:AM4) -> 1080000
A5: Industrial design contractor | B5: TremoSense | D5: 45000 | E5: 45000 | F5: 0 | G5: 0 | H5: 0 | I5: 0 | J5: 0 | K5: 0 | L5: 0 | M5: 0 | N5: 0 | O5: 0 | P5: 0 | Q5: 0 | R5: 0 | S5: 0 | T5: 0 | U5: 0 | V5: 0 | W5: 0 | X5: 0 | Y5: 0 | Z5: 0 | AA5: 0 | AB5: 0 | AC5: 0 | AD5: 0 | AE5: 0 | AF5: 0 | AG5: 0 | AH5: 0 | AI5: 0 | AJ5: 0 | AK5: 0 | AL5: 0 | AM5: 0 | AN5: =SUM(D5:O5) -> 90000 | AO5: =SUM(D5:I5) -> 90000 | AP5: =SUM(J5:U5) -> 0 | AQ5: =SUM(P5:AA5) -> 0 | AR5: =SUM(AB5:AM5) -> 0 | AW5: TS acquisition spend M12–M36 | AX5: =SUM(O21:AM21)+SUM(O25:AM25) -> 2805000
A6: Prototyping materials | B6: Shared | D6: 25000 | E6: 25000 | F6: 25000 | G6: 25000 | H6: 25000 | I6: 25000 | J6: 15000 | K6: 15000 | L6: 15000 | M6: 15000 | N6: 15000 | O6: 15000 | P6: 15000 | Q6: 15000 | R6: 15000 | S6: 15000 | T6: 15000 | U6: 15000 | V6: 15000 | W6: 15000 | X6: 15000 | Y6: 15000 | Z6: 15000 | AA6: 15000 | AB6: 15000 | AC6: 15000 | AD6: 15000 | AE6: 15000 | AF6: 15000 | AG6: 15000 | AH6: 15000 | AI6: 15000 | AJ6: 15000 | AK6: 15000 | AL6: 15000 | AM6: 15000 | AN6: =SUM(D6:O6) -> 240000 | AO6: =SUM(D6:I6) -> 150000 | AP6: =SUM(J6:U6) -> 180000 | AQ6: =SUM(P6:AA6) -> 180000 | AR6: =SUM(AB6:AM6) -> 180000 | AW6: TS units M12–M36 | AX6: =SUM(O34:AM34) -> 2600
A7: Tools, cloud, software | B7: Shared | D7: 8000 | E7: 8000 | F7: 8000 | G7: 8000 | H7: 8000 | I7: 8000 | J7: 8000 | K7: 8000 | L7: 8000 | M7: 8000 | N7: 8000 | O7: 8000 | P7: 8000 | Q7: 8000 | R7: 8000 | S7: 8000 | T7: 8000 | U7: 8000 | V7: 8000 | W7: 8000 | X7: 8000 | Y7: 8000 | Z7: 8000 | AA7: 8000 | AB7: 15000 | AC7: 15000 | AD7: 15000 | AE7: 15000 | AF7: 15000 | AG7: 15000 | AH7: 15000 | AI7: 15000 | AJ7: 15000 | AK7: 15000 | AL7: 15000 | AM7: 15000 | AN7: =SUM(D7:O7) -> 96000 | AO7: =SUM(D7:I7) -> 48000 | AP7: =SUM(J7:U7) -> 96000 | AQ7: =SUM(P7:AA7) -> 96000 | AR7: =SUM(AB7:AM7) -> 180000
A8: Legal, accounting, admin | B8: Shared | D8: 25000 | E8: 12000 | F8: 12000 | G8: 12000 | H8: 12000 | I8: 12000 | J8: 12000 | K8: 12000 | L8: 12000 | M8: 12000 | N8: 12000 | O8: 12000 | P8: 12000 | Q8: 12000 | R8: 12000 | S8: 12000 | T8: 12000 | U8: 12000 | V8: 12000 | W8: 12000 | X8: 12000 | Y8: 12000 | Z8: 12000 | AA8: 12000 | AB8: 20000 | AC8: 20000 | AD8: 20000 | AE8: 20000 | AF8: 20000 | AG8: 20000 | AH8: 20000 | AI8: 20000 | AJ8: 20000 | AK8: 20000 | AL8: 20000 | AM8: 20000 | AN8: =SUM(D8:O8) -> 157000 | AO8: =SUM(D8:I8) -> 85000 | AP8: =SUM(J8:U8) -> 144000 | AQ8: =SUM(P8:AA8) -> 144000 | AR8: =SUM(AB8:AM8) -> 240000
A9: Patent: attorney + filing fees | B9: Shared | D9: 0 | E9: 55000 | F9: 0 | G9: 0 | H9: 0 | I9: 0 | J9: 0 | K9: 0 | L9: 0 | M9: 0 | N9: 0 | O9: 65000 | P9: 0 | Q9: 0 | R9: 0 | S9: 0 | T9: 0 | U9: 0 | V9: 0 | W9: 0 | X9: 0 | Y9: 0 | Z9: 0 | AA9: 0 | AB9: 0 | AC9: 0 | AD9: 0 | AE9: 0 | AF9: 0 | AG9: 40000 | AH9: 0 | AI9: 0 | AJ9: 0 | AK9: 0 | AL9: 0 | AM9: 0 | AN9: =SUM(D9:O9) -> 120000 | AO9: =SUM(D9:I9) -> 55000 | AP9: =SUM(J9:U9) -> 65000 | AQ9: =SUM(P9:AA9) -> 0 | AR9: =SUM(AB9:AM9) -> 40000
A10: TremoSense study units (12 × Scenario A cost) | B10: TremoSense | D10: 0 | E10: 0 | F10: =12*'TremoSense Costs'!B12 -> 58341.468 | G10: 0 | H10: 0 | I10: 0 | J10: 0 | K10: 0 | L10: 0 | M10: 0 | N10: 0 | O10: 0 | P10: 0 | Q10: 0 | R10: 0 | S10: 0 | T10: 0 | U10: 0 | V10: 0 | W10: 0 | X10: 0 | Y10: 0 | Z10: 0 | AA10: 0 | AB10: 0 | AC10: 0 | AD10: 0 | AE10: 0 | AF10: 0 | AG10: 0 | AH10: 0 | AI10: 0 | AJ10: 0 | AK10: 0 | AL10: 0 | AM10: 0 | AN10: =SUM(D10:O10) -> 58341.468 | AO10: =SUM(D10:I10) -> 58341.468 | AP10: =SUM(J10:U10) -> 0 | AQ10: =SUM(P10:AA10) -> 0 | AR10: =SUM(AB10:AM10) -> 0
A11: TremoSense ethics approval + user study (n ≥ 10) | B11: TremoSense | D11: 0 | E11: 0 | F11: 0 | G11: 40000 | H11: 30000 | I11: 30000 | J11: 0 | K11: 0 | L11: 0 | M11: 0 | N11: 0 | O11: 0 | P11: 0 | Q11: 0 | R11: 0 | S11: 0 | T11: 0 | U11: 0 | V11: 0 | W11: 0 | X11: 0 | Y11: 0 | Z11: 0 | AA11: 0 | AB11: 0 | AC11: 0 | AD11: 0 | AE11: 0 | AF11: 0 | AG11: 0 | AH11: 0 | AI11: 0 | AJ11: 0 | AK11: 0 | AL11: 0 | AM11: 0 | AN11: =SUM(D11:O11) -> 100000 | AO11: =SUM(D11:I11) -> 100000 | AP11: =SUM(J11:U11) -> 0 | AQ11: =SUM(P11:AA11) -> 0 | AR11: =SUM(AB11:AM11) -> 0
A12: Regulatory: classification opinion + CDSCO filing | B12: TremoSense | D12: 0 | E12: 0 | F12: 0 | G12: 30000 | H12: 0 | I12: 0 | J12: 0 | K12: 0 | L12: 40000 | M12: 40000 | N12: 0 | O12: 0 | P12: 0 | Q12: 0 | R12: 0 | S12: 0 | T12: 0 | U12: 0 | V12: 0 | W12: 0 | X12: 0 | Y12: 0 | Z12: 0 | AA12: 0 | AB12: 0 | AC12: 0 | AD12: 0 | AE12: 0 | AF12: 0 | AG12: 0 | AH12: 0 | AI12: 0 | AJ12: 0 | AK12: 0 | AL12: 0 | AM12: 0 | AN12: =SUM(D12:O12) -> 110000 | AO12: =SUM(D12:I12) -> 30000 | AP12: =SUM(J12:U12) -> 80000 | AQ12: =SUM(P12:AA12) -> 0 | AR12: =SUM(AB12:AM12) -> 0
A13: Reference instruments (ECG strap, pulse oximeter, pedometer) | B13: ParkinSense | D13: 0 | E13: 0 | F13: 0 | G13: 0 | H13: 0 | I13: 0 | J13: 110000 | K13: 0 | L13: 0 | M13: 0 | N13: 0 | O13: 0 | P13: 0 | Q13: 0 | R13: 0 | S13: 0 | T13: 0 | U13: 0 | V13: 0 | W13: 0 | X13: 0 | Y13: 0 | Z13: 0 | AA13: 0 | AB13: 0 | AC13: 0 | AD13: 0 | AE13: 0 | AF13: 0 | AG13: 0 | AH13: 0 | AI13: 0 | AJ13: 0 | AK13: 0 | AL13: 0 | AM13: 0 | AN13: =SUM(D13:O13) -> 110000 | AO13: =SUM(D13:I13) -> 0 | AP13: =SUM(J13:U13) -> 110000 | AQ13: =SUM(P13:AA13) -> 0 | AR13: =SUM(AB13:AM13) -> 0
A14: ParkinSense bench accuracy study | B14: ParkinSense | D14: 0 | E14: 0 | F14: 0 | G14: 0 | H14: 0 | I14: 0 | J14: 0 | K14: 25000 | L14: 25000 | M14: 25000 | N14: 0 | O14: 0 | P14: 0 | Q14: 0 | R14: 0 | S14: 0 | T14: 0 | U14: 0 | V14: 0 | W14: 0 | X14: 0 | Y14: 0 | Z14: 0 | AA14: 0 | AB14: 0 | AC14: 0 | AD14: 0 | AE14: 0 | AF14: 0 | AG14: 0 | AH14: 0 | AI14: 0 | AJ14: 0 | AK14: 0 | AL14: 0 | AM14: 0 | AN14: =SUM(D14:O14) -> 75000 | AO14: =SUM(D14:I14) -> 0 | AP14: =SUM(J14:U14) -> 75000 | AQ14: =SUM(P14:AA14) -> 0 | AR14: =SUM(AB14:AM14) -> 0
A15: ParkinSense RUO kit devices (5 × COGS per kit sold) | B15: ParkinSense | D15: =D37*5*Assumptions!$C$27 -> 0 | E15: =E37*5*Assumptions!$C$27 -> 0 | F15: =F37*5*Assumptions!$C$27 -> 0 | G15: =G37*5*Assumptions!$C$27 -> 0 | H15: =H37*5*Assumptions!$C$27 -> 0 | I15: =I37*5*Assumptions!$C$27 -> 0 | J15: =J37*5*Assumptions!$C$27 -> 0 | K15: =K37*5*Assumptions!$C$27 -> 0 | ... AM15: =AM37*5*Assumptions!$C$27 -> 17650 | AN15: =SUM(D15:O15) -> 35300 | AO15: =SUM(D15:I15) -> 0 | AP15: =SUM(J15:U15) -> 88250 | AQ15: =SUM(P15:AA15) -> 158850 | AR15: =SUM(AB15:AM15) -> 211800
A16: Hardware & test engineering (done by the founders, no hire) | B16: Shared | D16: 0 | E16: 0 | F16: 0 | G16: 0 | H16: 0 | I16: 0 | J16: 0 | K16: 0 | L16: 0 | M16: 0 | N16: 0 | O16: 0 | P16: 0 | Q16: 0 | R16: 0 | S16: 0 | T16: 0 | U16: 0 | V16: 0 | W16: 0 | X16: 0 | Y16: 0 | Z16: 0 | AA16: 0 | AB16: 0 | AC16: 0 | AD16: 0 | AE16: 0 | AF16: 0 | AG16: 0 | AH16: 0 | AI16: 0 | AJ16: 0 | AK16: 0 | AL16: 0 | AM16: 0 | AN16: =SUM(D16:O16) -> 0 | AO16: =SUM(D16:I16) -> 0 | AP16: =SUM(J16:U16) -> 0 | AQ16: =SUM(P16:AA16) -> 0 | AR16: =SUM(AB16:AM16) -> 0
A17: ISO 13485 QMS set-up + surveillance audits | B17: Shared | D17: 0 | E17: 0 | F17: 0 | G17: 0 | H17: 0 | I17: 0 | J17: 50000 | K17: 50000 | L17: 50000 | M17: 50000 | N17: 0 | O17: 0 | P17: 0 | Q17: 0 | R17: 0 | S17: 0 | T17: 0 | U17: 0 | V17: 0 | W17: 0 | X17: 0 | Y17: 40000 | Z17: 0 | AA17: 0 | AB17: 0 | AC17: 0 | AD17: 0 | AE17: 0 | AF17: 0 | AG17: 0 | AH17: 0 | AI17: 0 | AJ17: 0 | AK17: 40000 | AL17: 0 | AM17: 0 | AN17: =SUM(D17:O17) -> 200000 | AO17: =SUM(D17:I17) -> 0 | AP17: =SUM(J17:U17) -> 200000 | AQ17: =SUM(P17:AA17) -> 40000 | AR17: =SUM(AB17:AM17) -> 40000
A18: Electrical safety / EMC pre-compliance | B18: TremoSense | D18: 0 | E18: 0 | F18: 0 | G18: 0 | H18: 0 | I18: 0 | J18: 0 | K18: 0 | L18: 175000 | M18: 175000 | N18: 0 | O18: 0 | P18: 0 | Q18: 0 | R18: 0 | S18: 0 | T18: 0 | U18: 0 | V18: 0 | W18: 0 | X18: 0 | Y18: 0 | Z18: 0 | AA18: 0 | AB18: 0 | AC18: 0 | AD18: 0 | AE18: 0 | AF18: 0 | AG18: 0 | AH18: 0 | AI18: 0 | AJ18: 0 | AK18: 0 | AL18: 0 | AM18: 0 | AN18: =SUM(D18:O18) -> 350000 | AO18: =SUM(D18:I18) -> 0 | AP18: =SUM(J18:U18) -> 350000 | AQ18: =SUM(P18:AA18) -> 0 | AR18: =SUM(AB18:AM18) -> 0
A19: TremoSense pilot batch (100 × Scenario B cost) | B19: TremoSense | D19: 0 | E19: 0 | F19: 0 | G19: 0 | H19: 0 | I19: 0 | J19: 0 | K19: 0 | L19: 0 | M19: 0 | N19: =100*'TremoSense Costs'!C12 -> 483036.9 | O19: 0 | P19: 0 | Q19: 0 | R19: 0 | S19: 0 | T19: 0 | U19: 0 | V19: 0 | W19: 0 | X19: 0 | Y19: 0 | Z19: 0 | AA19: 0 | AB19: 0 | AC19: 0 | AD19: 0 | AE19: 0 | AF19: 0 | AG19: 0 | AH19: 0 | AI19: 0 | AJ19: 0 | AK19: 0 | AL19: 0 | AM19: 0 | AN19: =SUM(D19:O19) -> 483036.9 | AO19: =SUM(D19:I19) -> 0 | AP19: =SUM(J19:U19) -> 483036.9 | AQ19: =SUM(P19:AA19) -> 0 | AR19: =SUM(AB19:AM19) -> 0
A20: TremoSense restock (units × B cost to M18, × verified C cost from M19) | B20: TremoSense | D20: 0 | E20: 0 | F20: 0 | G20: 0 | H20: 0 | I20: 0 | J20: 0 | K20: 0 | L20: 0 | M20: 0 | N20: 0 | O20: 0 | P20: 0 | Q20: 0 | R20: =R34*'TremoSense Costs'!C12 -> 241518.45 | S20: =S34*'TremoSense Costs'!C12 -> 241518.45 | T20: =T34*'TremoSense Costs'!C12 -> 241518.45 | U20: =U34*'TremoSense Costs'!C12 -> 241518.45 | V20: =V34*'TremoSense Costs'!D12 -> 163200 | W20: =W34*'TremoSense Costs'!D12 -> 176800 | X20: =X34*'TremoSense Costs'!D12 -> 190400 | Y20: =Y34*'TremoSense Costs'!D12 -> 204000 | Z20: =Z34*'TremoSense Costs'!D12 -> 217600 | AA20: =AA34*'TremoSense Costs'!D12 -> 231200 | AB20: =AB34*'TremoSense Costs'!D12 -> 353600 | AC20: =AC34*'TremoSense Costs'!D12 -> 367200 | AD20: =AD34*'TremoSense Costs'!D12 -> 380800 | AE20: =AE34*'TremoSense Costs'!D12 -> 394400 | AF20: =AF34*'TremoSense Costs'!D12 -> 408000 | AG20: =AG34*'TremoSense Costs'!D12 -> 421600 | AH20: =AH34*'TremoSense Costs'!D12 -> 435200 | AI20: =AI34*'TremoSense Costs'!D12 -> 448800 | AJ20: =AJ34*'TremoSense Costs'!D12 -> 462400 | AK20: =AK34*'TremoSense Costs'!D12 -> 476000 | AL20: =AL34*'TremoSense Costs'!D12 -> 489600 | AM20: =AM34*'TremoSense Costs'!D12 -> 503200 | AN20: =SUM(D20:O20) -> 0 | AO20: =SUM(D20:I20) -> 0 | AP20: =SUM(J20:U20) -> 966073.8 | AQ20: =SUM(P20:AA20) -> 2149273.8 | AR20: =SUM(AB20:AM20) -> 5140800
A21: Clinic & OT outreach / marketing (TremoSense) | B21: TremoSense | D21: 0 | E21: 0 | F21: 0 | G21: 0 | H21: 0 | I21: 0 | J21: 0 | K21: 0 | L21: 0 | M21: 0 | N21: 0 | O21: 45000 | P21: 45000 | Q21: 45000 | R21: 45000 | S21: 45000 | T21: 45000 | U21: 45000 | V21: 75000 | W21: 75000 | X21: 75000 | Y21: 75000 | Z21: 75000 | AA21: 75000 | AB21: 100000 | AC21: 100000 | AD21: 100000 | AE21: 100000 | AF21: 100000 | AG21: 100000 | AH21: 100000 | AI21: 100000 | AJ21: 100000 | AK21: 100000 | AL21: 100000 | AM21: 100000 | AN21: =SUM(D21:O21) -> 45000 | AO21: =SUM(D21:I21) -> 0 | AP21: =SUM(J21:U21) -> 315000 | AQ21: =SUM(P21:AA21) -> 720000 | AR21: =SUM(AB21:AM21) -> 1200000
A22: ParkinSense wellness research pilot (incl. clinical-evaluation support) | B22: ParkinSense | D22: 0 | E22: 0 | F22: 0 | G22: 0 | H22: 0 | I22: 0 | J22: 0 | K22: 0 | L22: 0 | M22: 0 | N22: 30000 | O22: 30000 | P22: 30000 | Q22: 30000 | R22: 30000 | S22: 30000 | T22: 30000 | U22: 30000 | V22: 30000 | W22: 30000 | X22: 30000 | Y22: 30000 | Z22: 30000 | AA22: 30000 | AB22: 30000 | AC22: 30000 | AD22: 30000 | AE22: 30000 | AF22: 30000 | AG22: 30000 | AH22: 30000 | AI22: 30000 | AJ22: 30000 | AK22: 30000 | AL22: 30000 | AM22: 30000 | AN22: =SUM(D22:O22) -> 60000 | AO22: =SUM(D22:I22) -> 0 | AP22: =SUM(J22:U22) -> 240000 | AQ22: =SUM(P22:AA22) -> 360000 | AR22: =SUM(AB22:AM22) -> 360000
A23: Customer support & operations hire | B23: Shared | D23: 0 | E23: 0 | F23: 0 | G23: 0 | H23: 0 | I23: 0 | J23: 0 | K23: 0 | L23: 0 | M23: 0 | N23: 0 | O23: 0 | P23: 0 | Q23: 0 | R23: 0 | S23: 0 | T23: 0 | U23: 0 | V23: 35000 | W23: 35000 | X23: 35000 | Y23: 35000 | Z23: 35000 | AA23: 35000 | AB23: 35000 | AC23: 35000 | AD23: 35000 | AE23: 35000 | AF23: 35000 | AG23: 35000 | AH23: 35000 | AI23: 35000 | AJ23: 35000 | AK23: 35000 | AL23: 35000 | AM23: 35000 | AN23: =SUM(D23:O23) -> 0 | AO23: =SUM(D23:I23) -> 0 | AP23: =SUM(J23:U23) -> 0 | AQ23: =SUM(P23:AA23) -> 210000 | AR23: =SUM(AB23:AM23) -> 420000
A24: Clinic-network sales lead | B24: TremoSense | D24: 0 | E24: 0 | F24: 0 | G24: 0 | H24: 0 | I24: 0 | J24: 0 | K24: 0 | L24: 0 | M24: 0 | N24: 0 | O24: 0 | P24: 0 | Q24: 0 | R24: 0 | S24: 0 | T24: 0 | U24: 0 | V24: 50000 | W24: 50000 | X24: 50000 | Y24: 50000 | Z24: 50000 | AA24: 50000 | AB24: 50000 | AC24: 50000 | AD24: 50000 | AE24: 50000 | AF24: 50000 | AG24: 50000 | AH24: 50000 | AI24: 50000 | AJ24: 50000 | AK24: 50000 | AL24: 50000 | AM24: 50000 | AN24: =SUM(D24:O24) -> 0 | AO24: =SUM(D24:I24) -> 0 | AP24: =SUM(J24:U24) -> 0 | AQ24: =SUM(P24:AA24) -> 300000 | AR24: =SUM(AB24:AM24) -> 600000
A25: App & firmware engineer | B25: ParkinSense | D25: 0 | E25: 0 | F25: 0 | G25: 0 | H25: 0 | I25: 0 | J25: 0 | K25: 0 | L25: 0 | M25: 0 | N25: 0 | O25: 0 | P25: 0 | Q25: 0 | R25: 0 | S25: 0 | T25: 0 | U25: 0 | V25: 0 | W25: 0 | X25: 0 | Y25: 0 | Z25: 0 | AA25: 0 | AB25: 70000 | AC25: 70000 | AD25: 70000 | AE25: 70000 | AF25: 70000 | AG25: 70000 | AH25: 70000 | AI25: 70000 | AJ25: 70000 | AK25: 70000 | AL25: 70000 | AM25: 70000 | AN25: =SUM(D25:O25) -> 0 | AO25: =SUM(D25:I25) -> 0 | AP25: =SUM(J25:U25) -> 0 | AQ25: =SUM(P25:AA25) -> 0 | AR25: =SUM(AB25:AM25) -> 840000
A26: Injection-mould tooling (Scenario C) | B26: TremoSense | D26: 0 | E26: 0 | F26: 0 | G26: 0 | H26: 0 | I26: 0 | J26: 0 | K26: 0 | L26: 0 | M26: 0 | N26: 0 | O26: 0 | P26: 0 | Q26: 0 | R26: 0 | S26: 0 | T26: 0 | U26: =Assumptions!$C$30 -> 700000 | V26: 0 | W26: 0 | X26: 0 | Y26: 0 | Z26: 0 | AA26: 0 | AB26: 0 | AC26: 0 | AD26: 0 | AE26: 0 | AF26: 0 | AG26: 0 | AH26: 0 | AI26: 0 | AJ26: 0 | AK26: 0 | AL26: 0 | AM26: 0 | AN26: =SUM(D26:O26) -> 0 | AO26: =SUM(D26:I26) -> 0 | AP26: =SUM(J26:U26) -> 700000 | AQ26: =SUM(P26:AA26) -> 700000 | AR26: =SUM(AB26:AM26) -> 0
A27: ParkinSense wellness device inventory (units × COGS) | B27: ParkinSense | D27: =D39*Assumptions!$C$27 -> 0 | E27: =E39*Assumptions!$C$27 -> 0 | F27: =F39*Assumptions!$C$27 -> 0 | G27: =G39*Assumptions!$C$27 -> 0 | H27: =H39*Assumptions!$C$27 -> 0 | I27: =I39*Assumptions!$C$27 -> 0 | J27: =J39*Assumptions!$C$27 -> 0 | K27: =K39*Assumptions!$C$27 -> 0 | ... AM27: =AM39*Assumptions!$C$27 -> 600100 | AN27: =SUM(D27:O27) -> 0 | AO27: =SUM(D27:I27) -> 0 | AP27: =SUM(J27:U27) -> 0 | AQ27: =SUM(P27:AA27) -> 0 | AR27: =SUM(AB27:AM27) -> 4871400
A28: ParkinSense D2C acquisition (units × CAC) | B28: ParkinSense | D28: =D39*Assumptions!$C$33 -> 0 | E28: =E39*Assumptions!$C$33 -> 0 | F28: =F39*Assumptions!$C$33 -> 0 | G28: =G39*Assumptions!$C$33 -> 0 | H28: =H39*Assumptions!$C$33 -> 0 | I28: =I39*Assumptions!$C$33 -> 0 | J28: =J39*Assumptions!$C$33 -> 0 | K28: =K39*Assumptions!$C$33 -> 0 | ... AM28: =AM39*Assumptions!$C$33 -> 255000 | AN28: =SUM(D28:O28) -> 0 | AO28: =SUM(D28:I28) -> 0 | AP28: =SUM(J28:U28) -> 0 | AQ28: =SUM(P28:AA28) -> 0 | AR28: =SUM(AB28:AM28) -> 2070000
A29: ParkinSense subscription cloud cost (subscribers × cost) | B29: ParkinSense | D29: =D41*Assumptions!$C$28 -> 0 | E29: =E41*Assumptions!$C$28 -> 0 | F29: =F41*Assumptions!$C$28 -> 0 | G29: =G41*Assumptions!$C$28 -> 0 | H29: =H41*Assumptions!$C$28 -> 0 | I29: =I41*Assumptions!$C$28 -> 0 | J29: =J41*Assumptions!$C$28 -> 0 | K29: =K41*Assumptions!$C$28 -> 0 | ... AM29: =AM41*Assumptions!$C$28 -> 17808.132 | AN29: =SUM(D29:O29) -> 0 | AO29: =SUM(D29:I29) -> 0 | AP29: =SUM(J29:U29) -> 0 | AQ29: =SUM(P29:AA29) -> 0 | AR29: =SUM(AB29:AM29) -> 103245.49
A30: Subtotal | D30: =SUM(D4:D29) -> 133000 | E30: =SUM(E4:E29) -> 175000 | F30: =SUM(F4:F29) -> 133341.47 | G30: =SUM(G4:G29) -> 145000 | H30: =SUM(H4:H29) -> 105000 | I30: =SUM(I4:I29) -> 105000 | J30: =SUM(J4:J29) -> 255000 | K30: =SUM(K4:K29) -> 170000 | ... AM30: =SUM(AM4:AM29) -> 1818758.1 | AN30: =SUM(D30:O30) -> 2869678.4 | AO30: =SUM(D30:I30) -> 796341.47 | AP30: =SUM(J30:U30) -> 4812360.7 | AQ30: =SUM(P30:AA30) -> 5778123.8 | AR30: =SUM(AB30:AM30) -> 17577245
A31: Contingency | D31: =D30*Assumptions!$C$35 -> 13300 | E31: =E30*Assumptions!$C$35 -> 17500 | F31: =F30*Assumptions!$C$35 -> 13334.147 | G31: =G30*Assumptions!$C$35 -> 14500 | H31: =H30*Assumptions!$C$35 -> 10500 | I31: =I30*Assumptions!$C$35 -> 10500 | J31: =J30*Assumptions!$C$35 -> 25500 | K31: =K30*Assumptions!$C$35 -> 17000 | ... AM31: =AM30*Assumptions!$C$35 -> 181875.81 | AN31: =SUM(D31:O31) -> 286967.84 | AO31: =SUM(D31:I31) -> 79634.147 | AP31: =SUM(J31:U31) -> 481236.07 | AQ31: =SUM(P31:AA31) -> 577812.38 | AR31: =SUM(AB31:AM31) -> 1757724.5
A32: TOTAL CASH COSTS | D32: =D30+D31 -> 146300 | E32: =E30+E31 -> 192500 | F32: =F30+F31 -> 146675.61 | G32: =G30+G31 -> 159500 | H32: =H30+H31 -> 115500 | I32: =I30+I31 -> 115500 | J32: =J30+J31 -> 280500 | K32: =K30+K31 -> 187000 | ... AM32: =AM30+AM31 -> 2000633.9 | AN32: =SUM(D32:O32) -> 3156646.2 | AO32: =SUM(D32:I32) -> 875975.61 | AP32: =SUM(J32:U32) -> 5293596.8 | AQ32: =SUM(P32:AA32) -> 6355936.2 | AR32: =SUM(AB32:AM32) -> 19334970
A34: TremoSense units sold | B34: TremoSense | D34: 0 | E34: 0 | F34: 0 | G34: 0 | H34: 0 | I34: 0 | J34: 0 | K34: 0 | L34: 0 | M34: 0 | N34: 0 | O34: 15 | P34: 25 | Q34: 35 | R34: 50 | S34: 50 | T34: 50 | U34: 50 | V34: 60 | W34: 65 | X34: 70 | Y34: 75 | Z34: 80 | AA34: 85 | AB34: 130 | AC34: 135 | AD34: 140 | AE34: 145 | AF34: 150 | AG34: 155 | AH34: 160 | AI34: 165 | AJ34: 170 | AK34: 175 | AL34: 180 | AM34: 185 | AN34: =SUM(D34:O34) -> 15 | AO34: =SUM(D34:I34) -> 0 | AP34: =SUM(J34:U34) -> 275 | AQ34: =SUM(P34:AA34) -> 695 | AR34: =SUM(AB34:AM34) -> 1890
A35: TremoSense cash per unit (launch price to M18, post-cost price from M19) | B35: TremoSense | D35: =(IF(1<=18,Assumptions!$C$12,Assumptions!$C$14)/(1+Assumptions!$C$18))*(1-Assumptions!$C$20-Assumptions!$C$25)-Assumptions!$C$26 -> 7368.2857 | E35: =(IF(2<=18,Assumptions!$C$12,Assumptions!$C$14)/(1+Assumptions!$C$18))*(1-Assumptions!$C$20-Assumptions!$C$25)-Assumptions!$C$26 -> 7368.2857 | F35: =(IF(3<=18,Assumptions!$C$12,Assumptions!$C$14)/(1+Assumptions!$C$18))*(1-Assumptions!$C$20-Assumptions!$C$25)-Assumptions!$C$26 -> 7368.2857 | G35: =(IF(4<=18,Assumptions!$C$12,Assumptions!$C$14)/(1+Assumptions!$C$18))*(1-Assumptions!$C$20-Assumptions!$C$25)-Assumptions!$C$26 -> 7368.2857 | H35: =(IF(5<=18,Assumptions!$C$12,Assumptions!$C$14)/(1+Assumptions!$C$18))*(1-Assumptions!$C$20-Assumptions!$C$25)-Assumptions!$C$26 -> 7368.2857 | I35: =(IF(6<=18,Assumptions!$C$12,Assumptions!$C$14)/(1+Assumptions!$C$18))*(1-Assumptions!$C$20-Assumptions!$C$25)-Assumptions!$C$26 -> 7368.2857 | J35: =(IF(7<=18,Assumptions!$C$12,Assumptions!$C$14)/(1+Assumptions!$C$18))*(1-Assumptions!$C$20-Assumptions!$C$25)-Assumptions!$C$26 -> 7368.2857 | K35: =(IF(8<=18,Assumptions!$C$12,Assumptions!$C$14)/(1+Assumptions!$C$18))*(1-Assumptions!$C$20-Assumptions!$C$25)-Assumptions!$C$26 -> 7368.2857 | L35: =(IF(9<=18,Assumptions!$C$12,Assumptions!$C$14)/(1+Assumptions!$C$18))*(1-Assumptions!$C$20-Assumptions!$C$25)-Assumptions!$C$26 -> 7368.2857 | M35: =(IF(10<=18,Assumptions!$C$12,Assumptions!$C$14)/(1+Assumptions!$C$18))*(1-Assumptions!$C$20-Assumptions!$C$25)-Assumptions!$C$26 -> 7368.2857 | N35: =(IF(11<=18,Assumptions!$C$12,Assumptions!$C$14)/(1+Assumptions!$C$18))*(1-Assumptions!$C$20-Assumptions!$C$25)-Assumptions!$C$26 -> 7368.2857 | O35: =(IF(12<=18,Assumptions!$C$12,Assumptions!$C$14)/(1+Assumptions!$C$18))*(1-Assumptions!$C$20-Assumptions!$C$25)-Assumptions!$C$26 -> 7368.2857 | P35: =(IF(13<=18,Assumptions!$C$12,Assumptions!$C$14)/(1+Assumptions!$C$18))*(1-Assumptions!$C$20-Assumptions!$C$25)-Assumptions!$C$26 -> 7368.2857 | Q35: =(IF(14<=18,Assumptions!$C$12,Assumptions!$C$14)/(1+Assumptions!$C$18))*(1-Assumptions!$C$20-Assumptions!$C$25)-Assumptions!$C$26 -> 7368.2857 | R35: =(IF(15<=18,Assumptions!$C$12,Assumptions!$C$14)/(1+Assumptions!$C$18))*(1-Assumptions!$C$20-Assumptions!$C$25)-Assumptions!$C$26 -> 7368.2857 | S35: =(IF(16<=18,Assumptions!$C$12,Assumptions!$C$14)/(1+Assumptions!$C$18))*(1-Assumptions!$C$20-Assumptions!$C$25)-Assumptions!$C$26 -> 7368.2857 | T35: =(IF(17<=18,Assumptions!$C$12,Assumptions!$C$14)/(1+Assumptions!$C$18))*(1-Assumptions!$C$20-Assumptions!$C$25)-Assumptions!$C$26 -> 7368.2857 | U35: =(IF(18<=18,Assumptions!$C$12,Assumptions!$C$14)/(1+Assumptions!$C$18))*(1-Assumptions!$C$20-Assumptions!$C$25)-Assumptions!$C$26 -> 7368.2857 | V35: =(IF(19<=18,Assumptions!$C$12,Assumptions!$C$14)/(1+Assumptions!$C$18))*(1-Assumptions!$C$20-Assumptions!$C$25)-Assumptions!$C$26 -> 6606.381 | W35: =(IF(20<=18,Assumptions!$C$12,Assumptions!$C$14)/(1+Assumptions!$C$18))*(1-Assumptions!$C$20-Assumptions!$C$25)-Assumptions!$C$26 -> 6606.381 | X35: =(IF(21<=18,Assumptions!$C$12,Assumptions!$C$14)/(1+Assumptions!$C$18))*(1-Assumptions!$C$20-Assumptions!$C$25)-Assumptions!$C$26 -> 6606.381 | Y35: =(IF(22<=18,Assumptions!$C$12,Assumptions!$C$14)/(1+Assumptions!$C$18))*(1-Assumptions!$C$20-Assumptions!$C$25)-Assumptions!$C$26 -> 6606.381 | Z35: =(IF(23<=18,Assumptions!$C$12,Assumptions!$C$14)/(1+Assumptions!$C$18))*(1-Assumptions!$C$20-Assumptions!$C$25)-Assumptions!$C$26 -> 6606.381 | AA35: =(IF(24<=18,Assumptions!$C$12,Assumptions!$C$14)/(1+Assumptions!$C$18))*(1-Assumptions!$C$20-Assumptions!$C$25)-Assumptions!$C$26 -> 6606.381 | AB35: =(IF(25<=18,Assumptions!$C$12,Assumptions!$C$14)/(1+Assumptions!$C$18))*(1-Assumptions!$C$20-Assumptions!$C$25)-Assumptions!$C$26 -> 6606.381 | AC35: =(IF(26<=18,Assumptions!$C$12,Assumptions!$C$14)/(1+Assumptions!$C$18))*(1-Assumptions!$C$20-Assumptions!$C$25)-Assumptions!$C$26 -> 6606.381 | AD35: =(IF(27<=18,Assumptions!$C$12,Assumptions!$C$14)/(1+Assumptions!$C$18))*(1-Assumptions!$C$20-Assumptions!$C$25)-Assumptions!$C$26 -> 6606.381 | AE35: =(IF(28<=18,Assumptions!$C$12,Assumptions!$C$14)/(1+Assumptions!$C$18))*(1-Assumptions!$C$20-Assumptions!$C$25)-Assumptions!$C$26 -> 6606.381 | AF35: =(IF(29<=18,Assumptions!$C$12,Assumptions!$C$14)/(1+Assumptions!$C$18))*(1-Assumptions!$C$20-Assumptions!$C$25)-Assumptions!$C$26 -> 6606.381 | AG35: =(IF(30<=18,Assumptions!$C$12,Assumptions!$C$14)/(1+Assumptions!$C$18))*(1-Assumptions!$C$20-Assumptions!$C$25)-Assumptions!$C$26 -> 6606.381 | AH35: =(IF(31<=18,Assumptions!$C$12,Assumptions!$C$14)/(1+Assumptions!$C$18))*(1-Assumptions!$C$20-Assumptions!$C$25)-Assumptions!$C$26 -> 6606.381 | AI35: =(IF(32<=18,Assumptions!$C$12,Assumptions!$C$14)/(1+Assumptions!$C$18))*(1-Assumptions!$C$20-Assumptions!$C$25)-Assumptions!$C$26 -> 6606.381 | AJ35: =(IF(33<=18,Assumptions!$C$12,Assumptions!$C$14)/(1+Assumptions!$C$18))*(1-Assumptions!$C$20-Assumptions!$C$25)-Assumptions!$C$26 -> 6606.381 | AK35: =(IF(34<=18,Assumptions!$C$12,Assumptions!$C$14)/(1+Assumptions!$C$18))*(1-Assumptions!$C$20-Assumptions!$C$25)-Assumptions!$C$26 -> 6606.381 | AL35: =(IF(35<=18,Assumptions!$C$12,Assumptions!$C$14)/(1+Assumptions!$C$18))*(1-Assumptions!$C$20-Assumptions!$C$25)-Assumptions!$C$26 -> 6606.381 | AM35: =(IF(36<=18,Assumptions!$C$12,Assumptions!$C$14)/(1+Assumptions!$C$18))*(1-Assumptions!$C$20-Assumptions!$C$25)-Assumptions!$C$26 -> 6606.381
A36: Cash in — TremoSense | B36: TremoSense | D36: =D34*D35 -> 0 | E36: =E34*E35 -> 0 | F36: =F34*F35 -> 0 | G36: =G34*G35 -> 0 | H36: =H34*H35 -> 0 | I36: =I34*I35 -> 0 | J36: =J34*J35 -> 0 | K36: =K34*K35 -> 0 | ... AM36: =AM34*AM35 -> 1222180.5 | AN36: =SUM(D36:O36) -> 110524.29 | AO36: =SUM(D36:I36) -> 0 | AP36: =SUM(J36:U36) -> 2026278.6 | AQ36: =SUM(P36:AA36) -> 4789530 | AR36: =SUM(AB36:AM36) -> 12486060
A37: ParkinSense RUO kits sold | B37: ParkinSense | D37: 0 | E37: 0 | F37: 0 | G37: 0 | H37: 0 | I37: 0 | J37: 0 | K37: 0 | L37: 0 | M37: 1 | N37: 0 | O37: 1 | P37: 0 | Q37: 1 | R37: 0 | S37: 1 | T37: 0 | U37: 1 | V37: 1 | W37: 1 | X37: 1 | Y37: 1 | Z37: 1 | AA37: 1 | AB37: 1 | AC37: 1 | AD37: 1 | AE37: 1 | AF37: 1 | AG37: 1 | AH37: 1 | AI37: 1 | AJ37: 1 | AK37: 1 | AL37: 1 | AM37: 1 | AN37: =SUM(D37:O37) -> 2 | AO37: =SUM(D37:I37) -> 0 | AP37: =SUM(J37:U37) -> 5 | AQ37: =SUM(P37:AA37) -> 9 | AR37: =SUM(AB37:AM37) -> 12
A38: Cash in — ParkinSense RUO kits | B38: ParkinSense | D38: =D37*('Unit Economics'!$E$7-'Unit Economics'!$E$10-Assumptions!$C$29) -> 0 | E38: =E37*('Unit Economics'!$E$7-'Unit Economics'!$E$10-Assumptions!$C$29) -> 0 | F38: =F37*('Unit Economics'!$E$7-'Unit Economics'!$E$10-Assumptions!$C$29) -> 0 | G38: =G37*('Unit Economics'!$E$7-'Unit Economics'!$E$10-Assumptions!$C$29) -> 0 | H38: =H37*('Unit Economics'!$E$7-'Unit Economics'!$E$10-Assumptions!$C$29) -> 0 | I38: =I37*('Unit Economics'!$E$7-'Unit Economics'!$E$10-Assumptions!$C$29) -> 0 | J38: =J37*('Unit Economics'!$E$7-'Unit Economics'!$E$10-Assumptions!$C$29) -> 0 | K38: =K37*('Unit Economics'!$E$7-'Unit Economics'!$E$10-Assumptions!$C$29) -> 0 | ... AM38: =AM37*('Unit Economics'!$E$7-'Unit Economics'!$E$10-Assumptions!$C$29) -> 58308.475 | AN38: =SUM(D38:O38) -> 116616.95 | AO38: =SUM(D38:I38) -> 0 | AP38: =SUM(J38:U38) -> 291542.37 | AQ38: =SUM(P38:AA38) -> 524776.27 | AR38: =SUM(AB38:AM38) -> 699701.69
A39: ParkinSense wellness units sold (launch M25, after wellness beta) | B39: ParkinSense | D39: 0 | E39: 0 | F39: 0 | G39: 0 | H39: 0 | I39: 0 | J39: 0 | K39: 0 | L39: 0 | M39: 0 | N39: 0 | O39: 0 | P39: 0 | Q39: 0 | R39: 0 | S39: 0 | T39: 0 | U39: 0 | V39: 0 | W39: 0 | X39: 0 | Y39: 0 | Z39: 0 | AA39: 0 | AB39: 60 | AC39: 70 | AD39: 80 | AE39: 90 | AF39: 100 | AG39: 110 | AH39: 120 | AI39: 130 | AJ39: 140 | AK39: 150 | AL39: 160 | AM39: 170 | AN39: =SUM(D39:O39) -> 0 | AO39: =SUM(D39:I39) -> 0 | AP39: =SUM(J39:U39) -> 0 | AQ39: =SUM(P39:AA39) -> 0 | AR39: =SUM(AB39:AM39) -> 1380
A40: Cash in — ParkinSense devices | B40: ParkinSense | D40: =D39*('Unit Economics'!$C$7-'Unit Economics'!$C$9-'Unit Economics'!$C$10) -> 0 | E40: =E39*('Unit Economics'!$C$7-'Unit Economics'!$C$9-'Unit Economics'!$C$10) -> 0 | F40: =F39*('Unit Economics'!$C$7-'Unit Economics'!$C$9-'Unit Economics'!$C$10) -> 0 | G40: =G39*('Unit Economics'!$C$7-'Unit Economics'!$C$9-'Unit Economics'!$C$10) -> 0 | H40: =H39*('Unit Economics'!$C$7-'Unit Economics'!$C$9-'Unit Economics'!$C$10) -> 0 | I40: =I39*('Unit Economics'!$C$7-'Unit Economics'!$C$9-'Unit Economics'!$C$10) -> 0 | J40: =J39*('Unit Economics'!$C$7-'Unit Economics'!$C$9-'Unit Economics'!$C$10) -> 0 | K40: =K39*('Unit Economics'!$C$7-'Unit Economics'!$C$9-'Unit Economics'!$C$10) -> 0 | ... AM40: =AM39*('Unit Economics'!$C$7-'Unit Economics'!$C$9-'Unit Economics'!$C$10) -> 937038.56 | AN40: =SUM(D40:O40) -> 0 | AO40: =SUM(D40:I40) -> 0 | AP40: =SUM(J40:U40) -> 0 | AQ40: =SUM(P40:AA40) -> 0 | AR40: =SUM(AB40:AM40) -> 7606548.3
A41: ParkinSense active subscribers | B41: ParkinSense | D41: =D39*Assumptions!$C$34 -> 0 | E41: =D41*(1-Assumptions!$C$31)+E39*Assumptions!$C$34 -> 0 | F41: =E41*(1-Assumptions!$C$31)+F39*Assumptions!$C$34 -> 0 | G41: =F41*(1-Assumptions!$C$31)+G39*Assumptions!$C$34 -> 0 | H41: =G41*(1-Assumptions!$C$31)+H39*Assumptions!$C$34 -> 0 | I41: =H41*(1-Assumptions!$C$31)+I39*Assumptions!$C$34 -> 0 | J41: =I41*(1-Assumptions!$C$31)+J39*Assumptions!$C$34 -> 0 | K41: =J41*(1-Assumptions!$C$31)+K39*Assumptions!$C$34 -> 0 | L41: =K41*(1-Assumptions!$C$31)+L39*Assumptions!$C$34 -> 0 | ... AM41: =AL41*(1-Assumptions!$C$31)+AM39*Assumptions!$C$34 -> 445.2033
A42: Cash in — ParkinSense subscriptions | B42: ParkinSense | D42: =D41*'Unit Economics'!$D$7 -> 0 | E42: =E41*'Unit Economics'!$D$7 -> 0 | F42: =F41*'Unit Economics'!$D$7 -> 0 | G42: =G41*'Unit Economics'!$D$7 -> 0 | H42: =H41*'Unit Economics'!$D$7 -> 0 | I42: =I41*'Unit Economics'!$D$7 -> 0 | J42: =J41*'Unit Economics'!$D$7 -> 0 | K42: =K41*'Unit Economics'!$D$7 -> 0 | ... AM42: =AM41*'Unit Economics'!$D$7 -> 75080.895 | AN42: =SUM(D42:O42) -> 0 | AO42: =SUM(D42:I42) -> 0 | AP42: =SUM(J42:U42) -> 0 | AQ42: =SUM(P42:AA42) -> 0 | AR42: =SUM(AB42:AM42) -> 435293.5
...

Sheet Valuation
A1: Pre-money valuation — cost-to-duplicate (a floor, not a market price)
A3: Workstream | B3: Person-months | C3: Evidence | E3: Berkus-style scorecard (cross-check)
A4: ParkinSense: firmware v1–v4, BLE protocol, enclosure, power profiling | B4: 4 | C4: firmware/ (6 sketches), PPK II measurement, 3D-printed housing | E4: Sound idea (product risk) | F4: 1500000 | G4: Sourced need; two products; no interviews yet
A5: ParkinSense: motion / PPG / step pipelines, runtime, dashboards, app work, bench tests, paper | B5: 14.5 | C5: dashboard/python (~60 modules), reference recordings, paper | E5: Prototype (technology risk) | F5: 2000000 | G5: Two working prototypes with measured bench results
A6: TremoSense: EKF/LQR modelling, Simulink sweeps, Zephyr firmware, gimbal & power hardware, bench tests, paper | B6: 15.5 | C6: MATLAB_Simulink/, tremosense-app/, paper Table IV | E6: Quality team (execution risk) | F6: 1250000 | G6: Strong technical record and papers; no commercial track record
A7: Total person-months | B7: =SUM(B4:B6) -> 34 | E7: Strategic relationships (market risk) | F7: 1000000 | G7: ICMR evaluation in progress (founder-reported); no clinic partners yet
A8: Loaded rate | B8: =Assumptions!$C$39 -> 125000 | E8: Product rollout / sales (production risk) | F8: 250000 | G8: Costed BOM and pricing; no sales
A9: Prototype materials, rigs, instruments already spent (estimate) | B9: 225000 | E9: Berkus-style total (max ₹20 L per factor) | F9: =SUM(F4:F8) -> 6000000
A10: PRE-MONEY P0 = person-months × rate + materials | B10: =B7*B8+B9 -> 4475000 | C10: Excludes unfiled IP, brand, market. Replace person-months with logged hours. | E10: PROPOSED pre-money (negotiation target) | F10: =Assumptions!$C$44 -> 7500000 | G10: Premium over Berkus cross-check: | H10: =F10/F9-1 -> 0.25
A12: Valuation required to hit a dilution target (no ESOP): P = I × (1 − d) ÷ d
A13: Equity raised I | B13: P needed for 15% | C13: P needed for 20% | D13: Dilution at proposed P | E13: Assessment
A14: ='Funding Scenarios'!C7 -> 2821953.6 | B14: =A14*(1-Assumptions!$C$41)/Assumptions!$C$41 -> 15991071 | C14: =A14*(1-Assumptions!$C$42)/Assumptions!$C$42 -> 11287814 | D14: =IF(A14=0,0,A14/($F$10+A14)) -> 0.27339336 | E14: =IF(D14<=Assumptions!$C$41,"Within 15% at proposed P",IF(D14<=Assumptions!$C$42,"Within 15–20% at proposed P","Above 20% at proposed P")) -> Above 20% at proposed P
A15: ='Funding Scenarios'!D7 -> 4821953.6 | B15: =A15*(1-Assumptions!$C$41)/Assumptions!$C$41 -> 27324404 | C15: =A15*(1-Assumptions!$C$42)/Assumptions!$C$42 -> 19287814 | D15: =IF(A15=0,0,A15/($F$10+A15)) -> 0.39133028 | E15: =IF(D15<=Assumptions!$C$41,"Within 15% at proposed P",IF(D15<=Assumptions!$C$42,"Within 15–20% at proposed P","Above 20% at proposed P")) -> Above 20% at proposed P
A16: ='Funding Scenarios'!E7 -> 1051170.7 | B16: =A16*(1-Assumptions!$C$41)/Assumptions!$C$41 -> 5956634.2 | C16: =A16*(1-Assumptions!$C$42)/Assumptions!$C$42 -> 4204683 | D16: =IF(A16=0,0,A16/($F$10+A16)) -> 0.12292711 | E16: =IF(D16<=Assumptions!$C$41,"Within 15% at proposed P",IF(D16<=Assumptions!$C$42,"Within 15–20% at proposed P","Above 20% at proposed P")) -> Within 15% at proposed P
A17: ='Funding Scenarios'!F7 -> 1051170.7 | B17: =A17*(1-Assumptions!$C$41)/Assumptions!$C$41 -> 5956634.2 | C17: =A17*(1-Assumptions!$C$42)/Assumptions!$C$42 -> 4204683 | D17: =IF(A17=0,0,A17/($F$10+A17)) -> 0.12292711 | E17: =IF(D17<=Assumptions!$C$41,"Within 15% at proposed P",IF(D17<=Assumptions!$C$42,"Within 15–20% at proposed P","Above 20% at proposed P")) -> Within 15% at proposed P
A18: Rows: Scenario A, B, C (tranche 1), D (tranche 1).
A20: Milestone-1 round at each pre-money option (equity = Scenario C)
A21: Pre-money | B21: Investor % | C21: Founders % (after ESOP) | D21: Basis
A22: =$B$10 -> 4475000 | B22: ='Funding Scenarios'!$E$7/(A22+'Funding Scenarios'!$E$7) -> 0.19021684 | C22: =1-B22-Assumptions!$C$38 -> 0.75978316 | D22: Floor: cost-to-duplicate
A23: =Assumptions!$C$45 -> 6000000 | B23: ='Funding Scenarios'!$E$7/(A23+'Funding Scenarios'!$E$7) -> 0.14907748 | C23: =1-B23-Assumptions!$C$38 -> 0.80092252 | D23: Conservative ≈ Berkus cross-check
A24: =Assumptions!$C$44 -> 7500000 | B24: ='Funding Scenarios'!$E$7/(A24+'Funding Scenarios'!$E$7) -> 0.12292711 | C24: =1-B24-Assumptions!$C$38 -> 0.82707289 | D24: PROPOSED working target
A25: =Assumptions!$C$46 -> 10000000 | B25: ='Funding Scenarios'!$E$7/(A25+'Funding Scenarios'!$E$7) -> 0.095118496 | C25: =1-B25-Assumptions!$C$38 -> 0.8548815 | D25: Ambitious — only if substantiated

Sheet Funding Scenarios
A1: Funding scenarios — grant kept separate from equity; grant is APPLIED, NOT SECURED
A3: Line | C3: A · Grant secured, full plan | D3: B · Grant refused, full plan | E3: C · Smaller round to Milestone 1 | F3: D · Staged: tranche 1 now, tranche 2 at milestone
A4: Capital requirement covered by this round | C4: =Forecast!$D$68 -> 4821953.6 | D4: =Forecast!$D$68 -> 4821953.6 | E4: =Forecast!$D$69 -> 1051170.7 | F4: =Forecast!$D$69 -> 1051170.7
A5: Grant status | C5: Awarded (assumed in this scenario only) | D5: Refused | E5: Not assumed | F5: Applied; counted only if awarded
A6: Grant counted | C6: =Assumptions!$C$37 -> 2000000 | D6: 0 | E6: 0 | F6: 0
A7: Equity required now (I) | C7: =C4-C6 -> 2821953.6 | D7: =D4-D6 -> 4821953.6 | E7: =E4-E6 -> 1051170.7 | F7: =F4-F6 -> 1051170.7
A8: Pre-money (proposed working target; floor in Valuation!B10) | C8: =Valuation!$F$10 -> 7500000 | D8: =Valuation!$F$10 -> 7500000 | E8: =Valuation!$F$10 -> 7500000 | F8: =Valuation!$F$10 -> 7500000
A9: Post-money = P + I | C9: =C8+C7 -> 10321954 | D9: =D8+D7 -> 12321954 | E9: =E8+E7 -> 8551170.7 | F9: =F8+F7 -> 8551170.7
A10: Investor ownership = I ÷ post-money | C10: =C7/C9 -> 0.27339336 | D10: =D7/D9 -> 0.39133028 | E10: =E7/E9 -> 0.12292711 | F10: =F7/F9 -> 0.12292711
A11: ESOP pool | C11: =Assumptions!$C$38 -> 0.05 | D11: =Assumptions!$C$38 -> 0.05 | E11: =Assumptions!$C$38 -> 0.05 | F11: =Assumptions!$C$38 -> 0.05
A12: Founders combined = 100% − investor − ESOP | C12: =1-C10-C11 -> 0.67660664 | D12: =1-D10-D11 -> 0.55866972 | E12: =1-E10-E11 -> 0.82707289 | F12: =1-F10-F11 -> 0.82707289
A13: Runway funded | C13: To operating break-even + buffer | D13: To operating break-even + buffer | E13: M1–M6 + buffer (Milestone 1) | F13: M1–M6 now; rest to break-even from tranche 2 / grant
A14: Milestones reached with this money | C14: User study, QMS, EMC, CDSCO filing, TremoSense sales from M12, scale to break-even, ParkinSense wellness launch M25 | D14: Same as A | E14: TremoSense design freeze + user study result (kill/continue), provisional patent, CDSCO classification opinion | F14: Tranche 1 = C; tranche 2 = rest of A
A15: Main risk / trade-off | C15: Grant may not arrive or may arrive late | D15: Highest dilution at a cost-floor price | E15: Must raise again in ~6 months | F15: Two raises; tranche 2 terms depend on results
